Workbook

Sheet 说明
A1: 地缘政治维度整合矩阵：工作簿
A2: 《数字依赖与组织韧性》（Innocent Twagirumukiza，2026年10月）配套工具，对应第3.6节
A4: 本工作簿的用途
A5: 它帮助在网络风险分析的每个阶段纳入地缘政治维度，而不把它变成又一个分值。论文的分析框架（3.4）衡量结构性暴露；地缘政治层单独评定，并对优先级起调节作用。
A6: 使用方法
A7: 1. “分析阶段”工作表：找到当前所处的分析阶段，并提出相应的地缘政治问题。
A8: 2. “依赖类别”工作表：对每一项已绘入图谱的依赖，确定其类别及可能的地缘政治杠杆。
A9: 3. “评估表”工作表：每项依赖一行。填写蓝色单元格（下拉列表）：四个暴露维度、韧性，然后是三个地缘政治调节因子。
A10: 4. 填写证据等级（A至D）、信号来源和复核日期。如果激活程度为高但没有确立关联，或缺少证据等级，“检查”列会出现提示。
A11: 5. 查看结果：结构性暴露、地缘政治激活程度、韧性调整前后的优先级。最后选择决策：减少、分散、监控或抵消。
A12: 6. “汇总”工作表：按优先级和类别统计依赖的分布。
A13: 7. “参数”工作表：阈值和优先级矩阵可以修改，应按行业加以校准。
... A21: 论文：https://twagirumukiza.github.io/Cybersecurity-and-geopolitics-/

Sheet 分析阶段
A1: 矩阵1：分析阶段 × 地缘政治问题
A3: 序号 | B3: 阶段 | C3: 应提出的地缘政治问题 | D3: 可参考的可观察因素 | E3: 成果 | F3: 论文章节
A4: 1 | B4: 界定范围 | C4: 如果国际环境恶化，哪些关键职能会受到影响？ | D4: 所属行业、境外业务、在关键基础设施中的角色 | E4: 关键职能与依赖边界 | F4: 3.1
A5: 2 | B5: 绘制图谱 | C5: 我们依赖哪些外部资源（一级和二级、硬件、人工智能），它们位于何处或在法律上归属何处？ | D5: 所在地、适用的司法管辖、二级分包商、组件来源 | E5: 按五类划分的依赖清单 | F5: 7.1
A6: 3 | B6: 情景设定 | C6: 每项依赖可能被施加何种地缘政治杠杆？ | D6: 国家行动、制裁、出口管制、对核心节点施压、附带效应 | E6: 网络与非网络情景 | F6: 3.3
A7: 4 | B7: 评估 | C7: 五个维度的评级是什么？单独评定的地缘政治激活程度是什么？ | D7: 贸易限制、外交紧张、产业集中、法律约束、制裁、获得维护的难度 | E7: 每项依赖的评估表（“评估表”工作表） | F7: 3.4、4.4
A8: 5 | B8: 处置 | C8: 应当减少、分散、监控还是抵消这项依赖？ | D8: 替代时间、退出策略、备份协议 | E8: 有理有据的治理决策 | F8: 7.6
A9: 6 | B9: 测试 | C9: 如果该资源缺失48小时、一周、一个月，这项职能会怎样？ | D9: 降级程序、自主运行时长 | E9: 更新后的韧性评级 | F9: 7.3
A10: 7 | B10: 监测与复核 | C10: 哪些信号会触发对地缘政治层的重新评估？ | D10: 新的限制措施、制裁、官方归因、机构出版物 | E10: 复核日程与触发条件 | F10: 7.2

Sheet 依赖类别
A1: 矩阵2：依赖类别 × 地缘政治杠杆
A3: 类别 | B3: 可能的地缘政治杠杆 | C3: 需要关注的因素 | D3: 参考案例（证据等级）
A4: 软件 | B4: 针对供应商的国家行动，对其施加的法律约束 | C4: 供应商的司法管辖、工具权限、更新渠道 | D4: SolarWinds、NotPetya（A）
A5: 工业（OT） | B5: 对关键基础设施的破坏 | C5: 远程访问、是否保留手动程序 | D5: 乌克兰电网（A）
A6: 服务中介 | B6: 对核心节点施压，冲突的附带效应 | C6: 服务商的市场份额、行业集中度 | D6: Change Healthcare（C）
A7: 硬件 | B7: 出口限制、制裁 | C7: 某一国家在精炼和制造环节中的占比 | D7: 稀土（D）
A8: 算法 | B8: 对算力组件的出口管制，适用的司法管辖 | C8: 算力所在地、监管框架的稳定性 | D8: 人工智能与算力（D）

Sheet 评估表
A1: 矩阵3：每项依赖的分析评估表（地缘政治层与优先级排序）
A2: 蓝色单元格：需要填写（下拉列表）。灰色单元格：自动计算。EX-01 行：需要替换的虚构示例。
A4: 标识 | E4: 结构性框架（3.4） | J4: 地缘政治层（3.6） | P4: 结果 | U4: 决策与复核 | W4: 中间计算
A5: 编号 | B5: 依赖（资源或供应商） | C5: 类别 | D5: 所支撑的关键职能 | E5: 依赖 | F5: 集中度 | G5: 可替代性 | H5: 传导 | I5: 韧性 | J5: 被瞄准的概率 | K5: 中断的可能持续时间 | L5: 获得维护和更新的难度 | M5: 证据等级（A至D） | N5: 信号来源 | O5: 复核日期 | P5: 结构性暴露 | Q5: 地缘政治激活程度 | R5: 韧性调整前优先级 | S5: 最终优先级 | T5: 检查 | U5: 所作决策 | V5: 复核触发条件 | W5: 暴露平均值 | X5: 暴露等级（1-3） | Y5: 激活平均值 | Z5: 激活等级（1-3） | AA5: 基础优先级序号
A6: EX-01 | B6: 冷链监控系统，由服务商托管 | C6: 工业（OT） | D6: 维持所有场所的冷链运转 | E6: 高 | F6: 高 | G6: 中 | H6: 高 | I6: 低 | J6: 低 | K6: 低 | L6: 中 | M6: C | N6: 虚构示例（第7.6节）：未发现地缘政治信号 | O6: 2026-10 | P6: =IF(X6="","",INDEX(参数!$B$4:$B$6,X6)) -> 高 | Q6: =IF(Z6="","",INDEX(参数!$B$4:$B$6,Z6)) -> 低 | R6: =IF(OR(X6="",Z6=""),"",INDEX(参数!$B$26:$D$28,X6,Z6)) -> 监控 | S6: =IF(OR(AA6="",I6=""),"",INDEX(参数!$B$18:$B$22,MAX(1,MIN(5,AA6+2-MATCH(I6,参数!$B$9:$B$11,0))))) -> 处理 | T6: =IF(Z6="","",IF(AND(Z6=3,M6="C"),"请核实：激活程度为高，但没有确立的地缘政治关联（C级）",IF(AND(Z6>=2,M6=""),"请填写证据等级",""))) | U6: 抵消 | V6: 影响托管方的新限制或紧张局势；48小时演练未通过 | W6: =IF(COUNTA(E6:H6)<4,"",AVERAGE(MATCH(E6,参数!$B$4:$B$6,0),MATCH(F6,参数!$B$4:$B$6,0),MATCH(G6,参数!$B$4:$B$6,0),MATCH(H6,参数!$B$4:$B$6,0))) -> 2.75 | X6: =IF(W6="","",IF(W6>=参数!$B$14,3,IF(W6>=参数!$B$15,2,1))) -> 3 | Y6: =IF(COUNTA(J6:L6)<3,"",AVERAGE(MATCH(J6,参数!$B$4:$B$6,0),MATCH(K6,参数!$B$4:$B$6,0),MATCH(L6,参数!$B$4:$B$6,0))) -> 1.3333333 | Z6: =IF(Y6="","",IF(Y6>=参数!$B$14,3,IF(Y6>=参数!$B$15,2,1))) -> 1 | AA6: =IF(R6="","",MATCH(R6,参数!$B$18:$B$22,0)) -> 3
P7: =IF(X7="","",INDEX(参数!$B$4:$B$6,X7)) | Q7: =IF(Z7="","",INDEX(参数!$B$4:$B$6,Z7)) | R7: =IF(OR(X7="",Z7=""),"",INDEX(参数!$B$26:$D$28,X7,Z7)) | S7: =IF(OR(AA7="",I7=""),"",INDEX(参数!$B$18:$B$22,MAX(1,MIN(5,AA7+2-MATCH(I7,参数!$B$9:$B$11,0))))) | T7: =IF(Z7="","",IF(AND(Z7=3,M7="C"),"请核实：激活程度为高，但没有确立的地缘政治关联（C级）",IF(AND(Z7>=2,M7=""),"请填写证据等级",""))) | W7: =IF(COUNTA(E7:H7)<4,"",AVERAGE(MATCH(E7,参数!$B$4:$B$6,0),MATCH(F7,参数!$B$4:$B$6,0),MATCH(G7,参数!$B$4:$B$6,0),MATCH(H7,参数!$B$4:$B$6,0))) | X7: =IF(W7="","",IF(W7>=参数!$B$14,3,IF(W7>=参数!$B$15,2,1))) | Y7: =IF(COUNTA(J7:L7)<3,"",AVERAGE(MATCH(J7,参数!$B$4:$B$6,0),MATCH(K7,参数!$B$4:$B$6,0),MATCH(L7,参数!$B$4:$B$6,0))) | Z7: =IF(Y7="","",IF(Y7>=参数!$B$14,3,IF(Y7>=参数!$B$15,2,1))) | AA7: =IF(R7="","",MATCH(R7,参数!$B$18:$B$22,0))
P8: =IF(X8="","",INDEX(参数!$B$4:$B$6,X8)) | Q8: =IF(Z8="","",INDEX(参数!$B$4:$B$6,Z8)) | R8: =IF(OR(X8="",Z8=""),"",INDEX(参数!$B$26:$D$28,X8,Z8)) | S8: =IF(OR(AA8="",I8=""),"",INDEX(参数!$B$18:$B$22,MAX(1,MIN(5,AA8+2-MATCH(I8,参数!$B$9:$B$11,0))))) | T8: =IF(Z8="","",IF(AND(Z8=3,M8="C"),"请核实：激活程度为高，但没有确立的地缘政治关联（C级）",IF(AND(Z8>=2,M8=""),"请填写证据等级",""))) | W8: =IF(COUNTA(E8:H8)<4,"",AVERAGE(MATCH(E8,参数!$B$4:$B$6,0),MATCH(F8,参数!$B$4:$B$6,0),MATCH(G8,参数!$B$4:$B$6,0),MATCH(H8,参数!$B$4:$B$6,0))) | X8: =IF(W8="","",IF(W8>=参数!$B$14,3,IF(W8>=参数!$B$15,2,1))) | Y8: =IF(COUNTA(J8:L8)<3,"",AVERAGE(MATCH(J8,参数!$B$4:$B$6,0),MATCH(K8,参数!$B$4:$B$6,0),MATCH(L8,参数!$B$4:$B$6,0))) | Z8: =IF(Y8="","",IF(Y8>=参数!$B$14,3,IF(Y8>=参数!$B$15,2,1))) | AA8: =IF(R8="","",MATCH(R8,参数!$B$18:$B$22,0))
P9: =IF(X9="","",INDEX(参数!$B$4:$B$6,X9)) | Q9: =IF(Z9="","",INDEX(参数!$B$4:$B$6,Z9)) | R9: =IF(OR(X9="",Z9=""),"",INDEX(参数!$B$26:$D$28,X9,Z9)) | S9: =IF(OR(AA9="",I9=""),"",INDEX(参数!$B$18:$B$22,MAX(1,MIN(5,AA9+2-MATCH(I9,参数!$B$9:$B$11,0))))) | T9: =IF(Z9="","",IF(AND(Z9=3,M9="C"),"请核实：激活程度为高，但没有确立的地缘政治关联（C级）",IF(AND(Z9>=2,M9=""),"请填写证据等级",""))) | W9: =IF(COUNTA(E9:H9)<4,"",AVERAGE(MATCH(E9,参数!$B$4:$B$6,0),MATCH(F9,参数!$B$4:$B$6,0),MATCH(G9,参数!$B$4:$B$6,0),MATCH(H9,参数!$B$4:$B$6,0))) | X9: =IF(W9="","",IF(W9>=参数!$B$14,3,IF(W9>=参数!$B$15,2,1))) | Y9: =IF(COUNTA(J9:L9)<3,"",AVERAGE(MATCH(J9,参数!$B$4:$B$6,0),MATCH(K9,参数!$B$4:$B$6,0),MATCH(L9,参数!$B$4:$B$6,0))) | Z9: =IF(Y9="","",IF(Y9>=参数!$B$14,3,IF(Y9>=参数!$B$15,2,1))) | AA9: =IF(R9="","",MATCH(R9,参数!$B$18:$B$22,0))
P10: =IF(X10="","",INDEX(参数!$B$4:$B$6,X10)) | Q10: =IF(Z10="","",INDEX(参数!$B$4:$B$6,Z10)) | R10: =IF(OR(X10="",Z10=""),"",INDEX(参数!$B$26:$D$28,X10,Z10)) | S10: =IF(OR(AA10="",I10=""),"",INDEX(参数!$B$18:$B$22,MAX(1,MIN(5,AA10+2-MATCH(I10,参数!$B$9:$B$11,0))))) | T10: =IF(Z10="","",IF(AND(Z10=3,M10="C"),"请核实：激活程度为高，但没有确立的地缘政治关联（C级）",IF(AND(Z10>=2,M10=""),"请填写证据等级",""))) | W10: =IF(COUNTA(E10:H10)<4,"",AVERAGE(MATCH(E10,参数!$B$4:$B$6,0),MATCH(F10,参数!$B$4:$B$6,0),MATCH(G10,参数!$B$4:$B$6,0),MATCH(H10,参数!$B$4:$B$6,0))) | X10: =IF(W10="","",IF(W10>=参数!$B$14,3,IF(W10>=参数!$B$15,2,1))) | Y10: =IF(COUNTA(J10:L10)<3,"",AVERAGE(MATCH(J10,参数!$B$4:$B$6,0),MATCH(K10,参数!$B$4:$B$6,0),MATCH(L10,参数!$B$4:$B$6,0))) | Z10: =IF(Y10="","",IF(Y10>=参数!$B$14,3,IF(Y10>=参数!$B$15,2,1))) | AA10: =IF(R10="","",MATCH(R10,参数!$B$18:$B$22,0))
P11: =IF(X11="","",INDEX(参数!$B$4:$B$6,X11)) | Q11: =IF(Z11="","",INDEX(参数!$B$4:$B$6,Z11)) | R11: =IF(OR(X11="",Z11=""),"",INDEX(参数!$B$26:$D$28,X11,Z11)) | S11: =IF(OR(AA11="",I11=""),"",INDEX(参数!$B$18:$B$22,MAX(1,MIN(5,AA11+2-MATCH(I11,参数!$B$9:$B$11,0))))) | T11: =IF(Z11="","",IF(AND(Z11=3,M11="C"),"请核实：激活程度为高，但没有确立的地缘政治关联（C级）",IF(AND(Z11>=2,M11=""),"请填写证据等级",""))) | W11: =IF(COUNTA(E11:H11)<4,"",AVERAGE(MATCH(E11,参数!$B$4:$B$6,0),MATCH(F11,参数!$B$4:$B$6,0),MATCH(G11,参数!$B$4:$B$6,0),MATCH(H11,参数!$B$4:$B$6,0))) | X11: =IF(W11="","",IF(W11>=参数!$B$14,3,IF(W11>=参数!$B$15,2,1))) | Y11: =IF(COUNTA(J11:L11)<3,"",AVERAGE(MATCH(J11,参数!$B$4:$B$6,0),MATCH(K11,参数!$B$4:$B$6,0),MATCH(L11,参数!$B$4:$B$6,0))) | Z11: =IF(Y11="","",IF(Y11>=参数!$B$14,3,IF(Y11>=参数!$B$15,2,1))) | AA11: =IF(R11="","",MATCH(R11,参数!$B$18:$B$22,0))
P12: =IF(X12="","",INDEX(参数!$B$4:$B$6,X12)) | Q12: =IF(Z12="","",INDEX(参数!$B$4:$B$6,Z12)) | R12: =IF(OR(X12="",Z12=""),"",INDEX(参数!$B$26:$D$28,X12,Z12)) | S12: =IF(OR(AA12="",I12=""),"",INDEX(参数!$B$18:$B$22,MAX(1,MIN(5,AA12+2-MATCH(I12,参数!$B$9:$B$11,0))))) | T12: =IF(Z12="","",IF(AND(Z12=3,M12="C"),"请核实：激活程度为高，但没有确立的地缘政治关联（C级）",IF(AND(Z12>=2,M12=""),"请填写证据等级",""))) | W12: =IF(COUNTA(E12:H12)<4,"",AVERAGE(MATCH(E12,参数!$B$4:$B$6,0),MATCH(F12,参数!$B$4:$B$6,0),MATCH(G12,参数!$B$4:$B$6,0),MATCH(H12,参数!$B$4:$B$6,0))) | X12: =IF(W12="","",IF(W12>=参数!$B$14,3,IF(W12>=参数!$B$15,2,1))) | Y12: =IF(COUNTA(J12:L12)<3,"",AVERAGE(MATCH(J12,参数!$B$4:$B$6,0),MATCH(K12,参数!$B$4:$B$6,0),MATCH(L12,参数!$B$4:$B$6,0))) | Z12: =IF(Y12="","",IF(Y12>=参数!$B$14,3,IF(Y12>=参数!$B$15,2,1))) | AA12: =IF(R12="","",MATCH(R12,参数!$B$18:$B$22,0))
P13: =IF(X13="","",INDEX(参数!$B$4:$B$6,X13)) | Q13: =IF(Z13="","",INDEX(参数!$B$4:$B$6,Z13)) | R13: =IF(OR(X13="",Z13=""),"",INDEX(参数!$B$26:$D$28,X13,Z13)) | S13: =IF(OR(AA13="",I13=""),"",INDEX(参数!$B$18:$B$22,MAX(1,MIN(5,AA13+2-MATCH(I13,参数!$B$9:$B$11,0))))) | T13: =IF(Z13="","",IF(AND(Z13=3,M13="C"),"请核实：激活程度为高，但没有确立的地缘政治关联（C级）",IF(AND(Z13>=2,M13=""),"请填写证据等级",""))) | W13: =IF(COUNTA(E13:H13)<4,"",AVERAGE(MATCH(E13,参数!$B$4:$B$6,0),MATCH(F13,参数!$B$4:$B$6,0),MATCH(G13,参数!$B$4:$B$6,0),MATCH(H13,参数!$B$4:$B$6,0))) | X13: =IF(W13="","",IF(W13>=参数!$B$14,3,IF(W13>=参数!$B$15,2,1))) | Y13: =IF(COUNTA(J13:L13)<3,"",AVERAGE(MATCH(J13,参数!$B$4:$B$6,0),MATCH(K13,参数!$B$4:$B$6,0),MATCH(L13,参数!$B$4:$B$6,0))) | Z13: =IF(Y13="","",IF(Y13>=参数!$B$14,3,IF(Y13>=参数!$B$15,2,1))) | AA13: =IF(R13="","",MATCH(R13,参数!$B$18:$B$22,0))
P14: =IF(X14="","",INDEX(参数!$B$4:$B$6,X14)) | Q14: =IF(Z14="","",INDEX(参数!$B$4:$B$6,Z14)) | R14: =IF(OR(X14="",Z14=""),"",INDEX(参数!$B$26:$D$28,X14,Z14)) | S14: =IF(OR(AA14="",I14=""),"",INDEX(参数!$B$18:$B$22,MAX(1,MIN(5,AA14+2-MATCH(I14,参数!$B$9:$B$11,0))))) | T14: =IF(Z14="","",IF(AND(Z14=3,M14="C"),"请核实：激活程度为高，但没有确立的地缘政治关联（C级）",IF(AND(Z14>=2,M14=""),"请填写证据等级",""))) | W14: =IF(COUNTA(E14:H14)<4,"",AVERAGE(MATCH(E14,参数!$B$4:$B$6,0),MATCH(F14,参数!$B$4:$B$6,0),MATCH(G14,参数!$B$4:$B$6,0),MATCH(H14,参数!$B$4:$B$6,0))) | X14: =IF(W14="","",IF(W14>=参数!$B$14,3,IF(W14>=参数!$B$15,2,1))) | Y14: =IF(COUNTA(J14:L14)<3,"",AVERAGE(MATCH(J14,参数!$B$4:$B$6,0),MATCH(K14,参数!$B$4:$B$6,0),MATCH(L14,参数!$B$4:$B$6,0))) | Z14: =IF(Y14="","",IF(Y14>=参数!$B$14,3,IF(Y14>=参数!$B$15,2,1))) | AA14: =IF(R14="","",MATCH(R14,参数!$B$18:$B$22,0))
P15: =IF(X15="","",INDEX(参数!$B$4:$B$6,X15)) | Q15: =IF(Z15="","",INDEX(参数!$B$4:$B$6,Z15)) | R15: =IF(OR(X15="",Z15=""),"",INDEX(参数!$B$26:$D$28,X15,Z15)) | S15: =IF(OR(AA15="",I15=""),"",INDEX(参数!$B$18:$B$22,MAX(1,MIN(5,AA15+2-MATCH(I15,参数!$B$9:$B$11,0))))) | T15: =IF(Z15="","",IF(AND(Z15=3,M15="C"),"请核实：激活程度为高，但没有确立的地缘政治关联（C级）",IF(AND(Z15>=2,M15=""),"请填写证据等级",""))) | W15: =IF(COUNTA(E15:H15)<4,"",AVERAGE(MATCH(E15,参数!$B$4:$B$6,0),MATCH(F15,参数!$B$4:$B$6,0),MATCH(G15,参数!$B$4:$B$6,0),MATCH(H15,参数!$B$4:$B$6,0))) | X15: =IF(W15="","",IF(W15>=参数!$B$14,3,IF(W15>=参数!$B$15,2,1))) | Y15: =IF(COUNTA(J15:L15)<3,"",AVERAGE(MATCH(J15,参数!$B$4:$B$6,0),MATCH(K15,参数!$B$4:$B$6,0),MATCH(L15,参数!$B$4:$B$6,0))) | Z15: =IF(Y15="","",IF(Y15>=参数!$B$14,3,IF(Y15>=参数!$B$15,2,1))) | AA15: =IF(R15="","",MATCH(R15,参数!$B$18:$B$22,0))
P16: =IF(X16="","",INDEX(参数!$B$4:$B$6,X16)) | Q16: =IF(Z16="","",INDEX(参数!$B$4:$B$6,Z16)) | R16: =IF(OR(X16="",Z16=""),"",INDEX(参数!$B$26:$D$28,X16,Z16)) | S16: =IF(OR(AA16="",I16=""),"",INDEX(参数!$B$18:$B$22,MAX(1,MIN(5,AA16+2-MATCH(I16,参数!$B$9:$B$11,0))))) | T16: =IF(Z16="","",IF(AND(Z16=3,M16="C"),"请核实：激活程度为高，但没有确立的地缘政治关联（C级）",IF(AND(Z16>=2,M16=""),"请填写证据等级",""))) | W16: =IF(COUNTA(E16:H16)<4,"",AVERAGE(MATCH(E16,参数!$B$4:$B$6,0),MATCH(F16,参数!$B$4:$B$6,0),MATCH(G16,参数!$B$4:$B$6,0),MATCH(H16,参数!$B$4:$B$6,0))) | X16: =IF(W16="","",IF(W16>=参数!$B$14,3,IF(W16>=参数!$B$15,2,1))) | Y16: =IF(COUNTA(J16:L16)<3,"",AVERAGE(MATCH(J16,参数!$B$4:$B$6,0),MATCH(K16,参数!$B$4:$B$6,0),MATCH(L16,参数!$B$4:$B$6,0))) | Z16: =IF(Y16="","",IF(Y16>=参数!$B$14,3,IF(Y16>=参数!$B$15,2,1))) | AA16: =IF(R16="","",MATCH(R16,参数!$B$18:$B$22,0))
P17: =IF(X17="","",INDEX(参数!$B$4:$B$6,X17)) | Q17: =IF(Z17="","",INDEX(参数!$B$4:$B$6,Z17)) | R17: =IF(OR(X17="",Z17=""),"",INDEX(参数!$B$26:$D$28,X17,Z17)) | S17: =IF(OR(AA17="",I17=""),"",INDEX(参数!$B$18:$B$22,MAX(1,MIN(5,AA17+2-MATCH(I17,参数!$B$9:$B$11,0))))) | T17: =IF(Z17="","",IF(AND(Z17=3,M17="C"),"请核实：激活程度为高，但没有确立的地缘政治关联（C级）",IF(AND(Z17>=2,M17=""),"请填写证据等级",""))) | W17: =IF(COUNTA(E17:H17)<4,"",AVERAGE(MATCH(E17,参数!$B$4:$B$6,0),MATCH(F17,参数!$B$4:$B$6,0),MATCH(G17,参数!$B$4:$B$6,0),MATCH(H17,参数!$B$4:$B$6,0))) | X17: =IF(W17="","",IF(W17>=参数!$B$14,3,IF(W17>=参数!$B$15,2,1))) | Y17: =IF(COUNTA(J17:L17)<3,"",AVERAGE(MATCH(J17,参数!$B$4:$B$6,0),MATCH(K17,参数!$B$4:$B$6,0),MATCH(L17,参数!$B$4:$B$6,0))) | Z17: =IF(Y17="","",IF(Y17>=参数!$B$14,3,IF(Y17>=参数!$B$15,2,1))) | AA17: =IF(R17="","",MATCH(R17,参数!$B$18:$B$22,0))
P18: =IF(X18="","",INDEX(参数!$B$4:$B$6,X18)) | Q18: =IF(Z18="","",INDEX(参数!$B$4:$B$6,Z18)) | R18: =IF(OR(X18="",Z18=""),"",INDEX(参数!$B$26:$D$28,X18,Z18)) | S18: =IF(OR(AA18="",I18=""),"",INDEX(参数!$B$18:$B$22,MAX(1,MIN(5,AA18+2-MATCH(I18,参数!$B$9:$B$11,0))))) | T18: =IF(Z18="","",IF(AND(Z18=3,M18="C"),"请核实：激活程度为高，但没有确立的地缘政治关联（C级）",IF(AND(Z18>=2,M18=""),"请填写证据等级",""))) | W18: =IF(COUNTA(E18:H18)<4,"",AVERAGE(MATCH(E18,参数!$B$4:$B$6,0),MATCH(F18,参数!$B$4:$B$6,0),MATCH(G18,参数!$B$4:$B$6,0),MATCH(H18,参数!$B$4:$B$6,0))) | X18: =IF(W18="","",IF(W18>=参数!$B$14,3,IF(W18>=参数!$B$15,2,1))) | Y18: =IF(COUNTA(J18:L18)<3,"",AVERAGE(MATCH(J18,参数!$B$4:$B$6,0),MATCH(K18,参数!$B$4:$B$6,0),MATCH(L18,参数!$B$4:$B$6,0))) | Z18: =IF(Y18="","",IF(Y18>=参数!$B$14,3,IF(Y18>=参数!$B$15,2,1))) | AA18: =IF(R18="","",MATCH(R18,参数!$B$18:$B$22,0))
... P45: =IF(X45="","",INDEX(参数!$B$4:$B$6,X45)) | Q45: =IF(Z45="","",INDEX(参数!$B$4:$B$6,Z45)) | R45: =IF(OR(X45="",Z45=""),"",INDEX(参数!$B$26:$D$28,X45,Z45)) | S45: =IF(OR(AA45="",I45=""),"",INDEX(参数!$B$18:$B$22,MAX(1,MIN(5,AA45+2-MATCH(I45,参数!$B$9:$B$11,0))))) | T45: =IF(Z45="","",IF(AND(Z45=3,M45="C"),"请核实：激活程度为高，但没有确立的地缘政治关联（C级）",IF(AND(Z45>=2,M45=""),"请填写证据等级",""))) | W45: =IF(COUNTA(E45:H45)<4,"",AVERAGE(MATCH(E45,参数!$B$4:$B$6,0),MATCH(F45,参数!$B$4:$B$6,0),MATCH(G45,参数!$B$4:$B$6,0),MATCH(H45,参数!$B$4:$B$6,0))) | X45: =IF(W45="","",IF(W45>=参数!$B$14,3,IF(W45>=参数!$B$15,2,1))) | Y45: =IF(COUNTA(J45:L45)<3,"",AVERAGE(MATCH(J45,参数!$B$4:$B$6,0),MATCH(K45,参数!$B$4:$B$6,0),MATCH(L45,参数!$B$4:$B$6,0))) | Z45: =IF(Y45="","",IF(Y45>=参数!$B$14,3,IF(Y45>=参数!$B$15,2,1))) | AA45: =IF(R45="","",MATCH(R45,参数!$B$18:$B$22,0))

Sheet 汇总
A1: 已分析依赖的汇总
A3: 按最终优先级分布
A4: 优先级 | B4: 数量
A5: 优先处理 | B5: =COUNTIF(评估表!$S$6:$S$45,A5) -> 0
A6: 处理 | B6: =COUNTIF(评估表!$S$6:$S$45,A6) -> 1
A7: 监控 | B7: =COUNTIF(评估表!$S$6:$S$45,A7) -> 0
A8: 接受并跟踪 | B8: =COUNTIF(评估表!$S$6:$S$45,A8) -> 0
A9: 接受 | B9: =COUNTIF(评估表!$S$6:$S$45,A9) -> 0
A10: 合计 | B10: =SUM(B5:B9) -> 1
A12: 按类别和优先级分布
A13: 类别 | B13: 优先处理 | C13: 处理 | D13: 监控 | E13: 接受并跟踪 | F13: 接受 | G13: 合计
A14: 软件 | B14: =COUNTIFS(评估表!$C$6:$C$45,$A14,评估表!$S$6:$S$45,B$13) -> 0 | C14: =COUNTIFS(评估表!$C$6:$C$45,$A14,评估表!$S$6:$S$45,C$13) -> 0 | D14: =COUNTIFS(评估表!$C$6:$C$45,$A14,评估表!$S$6:$S$45,D$13) -> 0 | E14: =COUNTIFS(评估表!$C$6:$C$45,$A14,评估表!$S$6:$S$45,E$13) -> 0 | F14: =COUNTIFS(评估表!$C$6:$C$45,$A14,评估表!$S$6:$S$45,F$13) -> 0 | G14: =SUM(B14:F14) -> 0
A15: 工业（OT） | B15: =COUNTIFS(评估表!$C$6:$C$45,$A15,评估表!$S$6:$S$45,B$13) -> 0 | C15: =COUNTIFS(评估表!$C$6:$C$45,$A15,评估表!$S$6:$S$45,C$13) -> 1 | D15: =COUNTIFS(评估表!$C$6:$C$45,$A15,评估表!$S$6:$S$45,D$13) -> 0 | E15: =COUNTIFS(评估表!$C$6:$C$45,$A15,评估表!$S$6:$S$45,E$13) -> 0 | F15: =COUNTIFS(评估表!$C$6:$C$45,$A15,评估表!$S$6:$S$45,F$13) -> 0 | G15: =SUM(B15:F15) -> 1
A16: 服务中介 | B16: =COUNTIFS(评估表!$C$6:$C$45,$A16,评估表!$S$6:$S$45,B$13) -> 0 | C16: =COUNTIFS(评估表!$C$6:$C$45,$A16,评估表!$S$6:$S$45,C$13) -> 0 | D16: =COUNTIFS(评估表!$C$6:$C$45,$A16,评估表!$S$6:$S$45,D$13) -> 0 | E16: =COUNTIFS(评估表!$C$6:$C$45,$A16,评估表!$S$6:$S$45,E$13) -> 0 | F16: =COUNTIFS(评估表!$C$6:$C$45,$A16,评估表!$S$6:$S$45,F$13) -> 0 | G16: =SUM(B16:F16) -> 0
A17: 硬件 | B17: =COUNTIFS(评估表!$C$6:$C$45,$A17,评估表!$S$6:$S$45,B$13) -> 0 | C17: =COUNTIFS(评估表!$C$6:$C$45,$A17,评估表!$S$6:$S$45,C$13) -> 0 | D17: =COUNTIFS(评估表!$C$6:$C$45,$A17,评估表!$S$6:$S$45,D$13) -> 0 | E17: =COUNTIFS(评估表!$C$6:$C$45,$A17,评估表!$S$6:$S$45,E$13) -> 0 | F17: =COUNTIFS(评估表!$C$6:$C$45,$A17,评估表!$S$6:$S$45,F$13) -> 0 | G17: =SUM(B17:F17) -> 0
A18: 算法 | B18: =COUNTIFS(评估表!$C$6:$C$45,$A18,评估表!$S$6:$S$45,B$13) -> 0 | C18: =COUNTIFS(评估表!$C$6:$C$45,$A18,评估表!$S$6:$S$45,C$13) -> 0 | D18: =COUNTIFS(评估表!$C$6:$C$45,$A18,评估表!$S$6:$S$45,D$13) -> 0 | E18: =COUNTIFS(评估表!$C$6:$C$45,$A18,评估表!$S$6:$S$45,E$13) -> 0 | F18: =COUNTIFS(评估表!$C$6:$C$45,$A18,评估表!$S$6:$S$45,F$13) -> 0 | G18: =SUM(B18:F18) -> 0
A20: 结构性暴露 × 地缘政治激活程度（依赖数量）
A21: 暴露 \ 激活 | B21: 低 | C21: 中 | D21: 高
A22: 高 | B22: =COUNTIFS(评估表!$X$6:$X$45,3,评估表!$Z$6:$Z$45,1) -> 1 | C22: =COUNTIFS(评估表!$X$6:$X$45,3,评估表!$Z$6:$Z$45,2) -> 0 | D22: =COUNTIFS(评估表!$X$6:$X$45,3,评估表!$Z$6:$Z$45,3) -> 0
A23: 中 | B23: =COUNTIFS(评估表!$X$6:$X$45,2,评估表!$Z$6:$Z$45,1) -> 0 | C23: =COUNTIFS(评估表!$X$6:$X$45,2,评估表!$Z$6:$Z$45,2) -> 0 | D23: =COUNTIFS(评估表!$X$6:$X$45,2,评估表!$Z$6:$Z$45,3) -> 0
A24: 低 | B24: =COUNTIFS(评估表!$X$6:$X$45,1,评估表!$Z$6:$Z$45,1) -> 0 | C24: =COUNTIFS(评估表!$X$6:$X$45,1,评估表!$Z$6:$Z$45,2) -> 0 | D24: =COUNTIFS(评估表!$X$6:$X$45,1,评估表!$Z$6:$Z$45,3) -> 0

Sheet 参数
A1: 参数（可修改）
A3: 暴露与激活等级（由低到高）
A4: 1 | B4: 低
A5: 2 | B5: 中
A6: 3 | B6: 高
A8: 韧性等级（由低到高）
A9: 1 | B9: 低
A10: 2 | B10: 部分
A11: 3 | B11: 强
A13: 平均值阈值
A14: “高”阈值（平均值 ≥） | B14: 2.5
A15: “中”阈值（平均值 ≥） | B15: 1.75
A17: 优先级刻度（由低到高）
A18: 1 | B18: 接受
A19: 2 | B19: 接受并跟踪
A20: 3 | B20: 监控
A21: 4 | B21: 处理
A22: 5 | B22: 优先处理
A24: 基础优先级矩阵（行：暴露；列：激活）
B25: 低 | C25: 中 | D25: 高
A26: 低 | B26: 接受 | C26: 接受并跟踪 | D26: 监控
A27: 中 | B27: 接受并跟踪 | C27: 监控 | D27: 处理
A28: 高 | B28: 监控 | C28: 处理 | D28: 优先处理
A30: 证据等级
A31: A | B31: 有文献记录的官方归因或决定（公共机构、起诉书、正式措施）
A32: B | B32: 有文献记录的地缘政治背景，但没有正式归因
A33: C | B33: 没有确立的地缘政治关联（仅有系统性影响）
A34: D | B34: 由非网络性质的公共决策或政策造成的中断（限制、制裁、出口管制）
A35: 如果在两个等级之间存疑，则采用预设地缘政治关联最少的那一级（论文附录A）。
A37: 依赖类别
B38: 软件
B39: 工业（OT）
B40: 服务中介
B41: 硬件
B42: 算法
A44: 可选决策
B45: 减少
B46: 分散
B47: 监控
B48: 抵消
...
