Workbook

Sheet Lisez-moi
A1: Matrice d'intégration de la dimension géopolitique : classeur de travail
A2: Complément à l'article « Dépendances numériques et résilience organisationnelle » (Innocent Twagirumukiza, octobre 2026), section 3.6
A4: À quoi sert ce classeur
A5: Il aide à intégrer la dimension géopolitique à chaque phase de l'analyse du risque cyber, sans en faire un score de plus. La grille de l'article (3.4) mesure l'exposition structurelle ; la couche géopolitique est notée à part et module la priorité.
A6: Mode d'emploi
A7: 1. Onglet « Phases » : repérez la phase d'analyse en cours et posez la question géopolitique correspondante.
A8: 2. Onglet « Categories » : pour chaque dépendance cartographiée, identifiez sa catégorie et les leviers géopolitiques possibles.
A9: 3. Onglet « Fiche » : une ligne par dépendance. Remplissez les cellules bleues (listes déroulantes) : les quatre dimensions d'exposition, la résilience, puis les trois modulateurs géopolitiques.
A10: 4. Renseignez le niveau de preuve (A à D), la source du signal et la date de revue. Une alerte apparaît dans la colonne « Contrôle » si l'activation est élevée sans lien établi, ou si le niveau de preuve manque.
A11: 5. Lisez le résultat : exposition structurelle, activation géopolitique, priorité avant puis après ajustement par la résilience. Choisissez enfin une décision : réduire, diversifier, surveiller ou compenser.
A12: 6. Onglet « Synthese » : répartition des dépendances par priorité et par catégorie.
A13: 7. Onglet « Parametres » : seuils et matrice de priorisation modifiables, à calibrer par secteur.
... A21: Article : https://twagirumukiza.github.io/Cybersecurity-and-geopolitics-/

Sheet Phases
A1: Matrice 1 : phases d'analyse × questions géopolitiques
A3: N° | B3: Phase | C3: Question géopolitique à poser | D3: Facteurs observables à consulter | E3: Livrable | F3: Réf. article
A4: 1 | B4: Cadrage | C4: Quelles fonctions essentielles souffriraient si le contexte international se dégradait ? | D4: Secteur d'activité, présence à l'étranger, rôle dans des infrastructures critiques | E4: Fonctions essentielles et périmètre de dépendance | F4: 3.1
A5: 2 | B5: Cartographie | C5: De quelles ressources externes dépend-on (rang 1 et 2, matériel, IA), et où sont-elles localisées ou juridiquement rattachées ? | D5: Localisation, juridiction applicable, sous-traitants de rang 2, origine des composants | E5: Dépendances classées dans les cinq catégories | F5: 7.1
A6: 3 | B6: Scénarios | C6: Quel levier géopolitique pourrait s'exercer sur chaque dépendance ? | D6: Opération étatique, sanctions, contrôle à l'exportation, pression sur un nœud central, effet collatéral | E6: Scénarios cyber et non cyber | F6: 3.3
A7: 4 | B7: Évaluation | C7: Quelle est la cotation sur les cinq dimensions, et quelle est l'activation géopolitique, notée à part ? | D7: Restrictions commerciales, tensions diplomatiques, concentration industrielle, contraintes juridiques, sanctions, accès à la maintenance | E7: Fiche par dépendance (onglet « Fiche ») | F7: 3.4, 4.4
A8: 5 | B8: Traitement | C8: Faut-il réduire, diversifier, surveiller ou compenser la dépendance ? | D8: Délai de substitution, stratégies de sortie, accords de secours | E8: Décision de gouvernance motivée | F8: 7.6
A9: 6 | B9: Tests | C9: Que devient la fonction si la ressource manque 48 heures, une semaine, un mois ? | D9: Procédures dégradées, autonomie en durée | E9: Cote de résilience mise à jour | F9: 7.3
A10: 7 | B10: Veille et revue | C10: Quel signal déclenche une réévaluation de la couche géopolitique ? | D10: Nouvelles restrictions, sanctions, attributions officielles, publications institutionnelles | E10: Calendrier et déclencheurs de révision | F10: 7.2

Sheet Categories
A1: Matrice 2 : catégories de dépendances × leviers géopolitiques
A3: Catégorie | B3: Levier géopolitique possible | C3: Facteurs à surveiller | D3: Cas de référence (niveau de preuve)
A4: Logicielle | B4: Opération étatique contre un éditeur, contraintes juridiques pesant sur lui | C4: Juridiction de l'éditeur, privilèges de l'outil, canal de mise à jour | D4: SolarWinds, NotPetya (A)
A5: Industrielle (OT) | B5: Sabotage d'infrastructures essentielles | C5: Accès à distance, existence de procédures manuelles | D5: Réseau électrique ukrainien (A)
A6: Intermédiaire de service | B6: Pression sur un nœud central, effet collatéral d'un conflit | C6: Part de marché du prestataire, concentration sectorielle | D6: Change Healthcare (C)
A7: Matérielle | B7: Restrictions à l'exportation, sanctions | C7: Part d'un pays dans le raffinage et la fabrication | D7: Terres rares (D)
A8: Algorithmique | B8: Contrôle des exportations de composants de calcul, juridiction applicable | C8: Localisation du calcul, stabilité du cadre réglementaire | D8: IA et calcul (D)

Sheet Fiche
A1: Matrice 3 : fiche d'analyse par dépendance (couche géopolitique et priorisation)
A2: Cellules bleues : à remplir (listes déroulantes). Cellules grises : calculées. Ligne EX-01 : exemple fictif à remplacer.
A4: Identification | E4: Grille structurelle (3.4) | J4: Couche géopolitique (3.6) | P4: Résultat | U4: Décision et revue | W4: Calculs intermédiaires
A5: ID | B5: Dépendance (ressource ou fournisseur) | C5: Catégorie | D5: Fonction essentielle soutenue | E5: Dépendance | F5: Concentration | G5: Substitution | H5: Propagation | I5: Résilience | J5: Probabilité de ciblage | K5: Durée probable de la perturbation | L5: Accès à la maintenance et aux mises à jour | M5: Niveau de preuve (A à D) | N5: Source du signal | O5: Date de revue | P5: Exposition structurelle | Q5: Activation géopolitique | R5: Priorité avant résilience | S5: Priorité finale | T5: Contrôle | U5: Décision retenue | V5: Déclencheur de révision | W5: Moyenne exposition | X5: Niveau exposition (1-3) | Y5: Moyenne activation | Z5: Niveau activation (1-3) | AA5: Rang priorité de base
A6: EX-01 | B6: Système de supervision de la chaîne du froid, hébergé chez un prestataire | C6: Industrielle (OT) | D6: Maintien de la chaîne du froid sur tous les sites | E6: Élevée | F6: Élevée | G6: Modérée | H6: Élevée | I6: Faible | J6: Faible | K6: Faible | L6: Modérée | M6: C | N6: Exemple fictif (section 7.6) : aucun signal géopolitique identifié | O6: 2026-10 | P6: =IF(X6="","",INDEX(Parametres!$B$4:$B$6,X6)) -> Élevée | Q6: =IF(Z6="","",INDEX(Parametres!$B$4:$B$6,Z6)) -> Faible | R6: =IF(OR(X6="",Z6=""),"",INDEX(Parametres!$B$26:$D$28,X6,Z6)) -> Surveiller | S6: =IF(OR(AA6="",I6=""),"",INDEX(Parametres!$B$18:$B$22,MAX(1,MIN(5,AA6+2-MATCH(I6,Parametres!$B$9:$B$11,0))))) -> Traiter | T6: =IF(Z6="","",IF(AND(Z6=3,M6="C"),"Vérifier : activation élevée sans lien géopolitique établi (niveau C)",IF(AND(Z6>=2,M6=""),"Renseigner le niveau de preuve",""))) | U6: Compenser | V6: Nouvelle restriction ou tension touchant l'hébergeur ; échec de l'exercice de 48 h | W6: =IF(COUNTA(E6:H6)<4,"",AVERAGE(MATCH(E6,Parametres!$B$4:$B$6,0),MATCH(F6,Parametres!$B$4:$B$6,0),MATCH(G6,Parametres!$B$4:$B$6,0),MATCH(H6,Parametres!$B$4:$B$6,0))) -> 2.75 | X6: =IF(W6="","",IF(W6>=Parametres!$B$14,3,IF(W6>=Parametres!$B$15,2,1))) -> 3 | Y6: =IF(COUNTA(J6:L6)<3,"",AVERAGE(MATCH(J6,Parametres!$B$4:$B$6,0),MATCH(K6,Parametres!$B$4:$B$6,0),MATCH(L6,Parametres!$B$4:$B$6,0))) -> 1.3333333 | Z6: =IF(Y6="","",IF(Y6>=Parametres!$B$14,3,IF(Y6>=Parametres!$B$15,2,1))) -> 1 | AA6: =IF(R6="","",MATCH(R6,Parametres!$B$18:$B$22,0)) -> 3
P7: =IF(X7="","",INDEX(Parametres!$B$4:$B$6,X7)) | Q7: =IF(Z7="","",INDEX(Parametres!$B$4:$B$6,Z7)) | R7: =IF(OR(X7="",Z7=""),"",INDEX(Parametres!$B$26:$D$28,X7,Z7)) | S7: =IF(OR(AA7="",I7=""),"",INDEX(Parametres!$B$18:$B$22,MAX(1,MIN(5,AA7+2-MATCH(I7,Parametres!$B$9:$B$11,0))))) | T7: =IF(Z7="","",IF(AND(Z7=3,M7="C"),"Vérifier : activation élevée sans lien géopolitique établi (niveau C)",IF(AND(Z7>=2,M7=""),"Renseigner le niveau de preuve",""))) | W7: =IF(COUNTA(E7:H7)<4,"",AVERAGE(MATCH(E7,Parametres!$B$4:$B$6,0),MATCH(F7,Parametres!$B$4:$B$6,0),MATCH(G7,Parametres!$B$4:$B$6,0),MATCH(H7,Parametres!$B$4:$B$6,0))) | X7: =IF(W7="","",IF(W7>=Parametres!$B$14,3,IF(W7>=Parametres!$B$15,2,1))) | Y7: =IF(COUNTA(J7:L7)<3,"",AVERAGE(MATCH(J7,Parametres!$B$4:$B$6,0),MATCH(K7,Parametres!$B$4:$B$6,0),MATCH(L7,Parametres!$B$4:$B$6,0))) | Z7: =IF(Y7="","",IF(Y7>=Parametres!$B$14,3,IF(Y7>=Parametres!$B$15,2,1))) | AA7: =IF(R7="","",MATCH(R7,Parametres!$B$18:$B$22,0))
P8: =IF(X8="","",INDEX(Parametres!$B$4:$B$6,X8)) | Q8: =IF(Z8="","",INDEX(Parametres!$B$4:$B$6,Z8)) | R8: =IF(OR(X8="",Z8=""),"",INDEX(Parametres!$B$26:$D$28,X8,Z8)) | S8: =IF(OR(AA8="",I8=""),"",INDEX(Parametres!$B$18:$B$22,MAX(1,MIN(5,AA8+2-MATCH(I8,Parametres!$B$9:$B$11,0))))) | T8: =IF(Z8="","",IF(AND(Z8=3,M8="C"),"Vérifier : activation élevée sans lien géopolitique établi (niveau C)",IF(AND(Z8>=2,M8=""),"Renseigner le niveau de preuve",""))) | W8: =IF(COUNTA(E8:H8)<4,"",AVERAGE(MATCH(E8,Parametres!$B$4:$B$6,0),MATCH(F8,Parametres!$B$4:$B$6,0),MATCH(G8,Parametres!$B$4:$B$6,0),MATCH(H8,Parametres!$B$4:$B$6,0))) | X8: =IF(W8="","",IF(W8>=Parametres!$B$14,3,IF(W8>=Parametres!$B$15,2,1))) | Y8: =IF(COUNTA(J8:L8)<3,"",AVERAGE(MATCH(J8,Parametres!$B$4:$B$6,0),MATCH(K8,Parametres!$B$4:$B$6,0),MATCH(L8,Parametres!$B$4:$B$6,0))) | Z8: =IF(Y8="","",IF(Y8>=Parametres!$B$14,3,IF(Y8>=Parametres!$B$15,2,1))) | AA8: =IF(R8="","",MATCH(R8,Parametres!$B$18:$B$22,0))
P9: =IF(X9="","",INDEX(Parametres!$B$4:$B$6,X9)) | Q9: =IF(Z9="","",INDEX(Parametres!$B$4:$B$6,Z9)) | R9: =IF(OR(X9="",Z9=""),"",INDEX(Parametres!$B$26:$D$28,X9,Z9)) | S9: =IF(OR(AA9="",I9=""),"",INDEX(Parametres!$B$18:$B$22,MAX(1,MIN(5,AA9+2-MATCH(I9,Parametres!$B$9:$B$11,0))))) | T9: =IF(Z9="","",IF(AND(Z9=3,M9="C"),"Vérifier : activation élevée sans lien géopolitique établi (niveau C)",IF(AND(Z9>=2,M9=""),"Renseigner le niveau de preuve",""))) | W9: =IF(COUNTA(E9:H9)<4,"",AVERAGE(MATCH(E9,Parametres!$B$4:$B$6,0),MATCH(F9,Parametres!$B$4:$B$6,0),MATCH(G9,Parametres!$B$4:$B$6,0),MATCH(H9,Parametres!$B$4:$B$6,0))) | X9: =IF(W9="","",IF(W9>=Parametres!$B$14,3,IF(W9>=Parametres!$B$15,2,1))) | Y9: =IF(COUNTA(J9:L9)<3,"",AVERAGE(MATCH(J9,Parametres!$B$4:$B$6,0),MATCH(K9,Parametres!$B$4:$B$6,0),MATCH(L9,Parametres!$B$4:$B$6,0))) | Z9: =IF(Y9="","",IF(Y9>=Parametres!$B$14,3,IF(Y9>=Parametres!$B$15,2,1))) | AA9: =IF(R9="","",MATCH(R9,Parametres!$B$18:$B$22,0))
P10: =IF(X10="","",INDEX(Parametres!$B$4:$B$6,X10)) | Q10: =IF(Z10="","",INDEX(Parametres!$B$4:$B$6,Z10)) | R10: =IF(OR(X10="",Z10=""),"",INDEX(Parametres!$B$26:$D$28,X10,Z10)) | S10: =IF(OR(AA10="",I10=""),"",INDEX(Parametres!$B$18:$B$22,MAX(1,MIN(5,AA10+2-MATCH(I10,Parametres!$B$9:$B$11,0))))) | T10: =IF(Z10="","",IF(AND(Z10=3,M10="C"),"Vérifier : activation élevée sans lien géopolitique établi (niveau C)",IF(AND(Z10>=2,M10=""),"Renseigner le niveau de preuve",""))) | W10: =IF(COUNTA(E10:H10)<4,"",AVERAGE(MATCH(E10,Parametres!$B$4:$B$6,0),MATCH(F10,Parametres!$B$4:$B$6,0),MATCH(G10,Parametres!$B$4:$B$6,0),MATCH(H10,Parametres!$B$4:$B$6,0))) | X10: =IF(W10="","",IF(W10>=Parametres!$B$14,3,IF(W10>=Parametres!$B$15,2,1))) | Y10: =IF(COUNTA(J10:L10)<3,"",AVERAGE(MATCH(J10,Parametres!$B$4:$B$6,0),MATCH(K10,Parametres!$B$4:$B$6,0),MATCH(L10,Parametres!$B$4:$B$6,0))) | Z10: =IF(Y10="","",IF(Y10>=Parametres!$B$14,3,IF(Y10>=Parametres!$B$15,2,1))) | AA10: =IF(R10="","",MATCH(R10,Parametres!$B$18:$B$22,0))
P11: =IF(X11="","",INDEX(Parametres!$B$4:$B$6,X11)) | Q11: =IF(Z11="","",INDEX(Parametres!$B$4:$B$6,Z11)) | R11: =IF(OR(X11="",Z11=""),"",INDEX(Parametres!$B$26:$D$28,X11,Z11)) | S11: =IF(OR(AA11="",I11=""),"",INDEX(Parametres!$B$18:$B$22,MAX(1,MIN(5,AA11+2-MATCH(I11,Parametres!$B$9:$B$11,0))))) | T11: =IF(Z11="","",IF(AND(Z11=3,M11="C"),"Vérifier : activation élevée sans lien géopolitique établi (niveau C)",IF(AND(Z11>=2,M11=""),"Renseigner le niveau de preuve",""))) | W11: =IF(COUNTA(E11:H11)<4,"",AVERAGE(MATCH(E11,Parametres!$B$4:$B$6,0),MATCH(F11,Parametres!$B$4:$B$6,0),MATCH(G11,Parametres!$B$4:$B$6,0),MATCH(H11,Parametres!$B$4:$B$6,0))) | X11: =IF(W11="","",IF(W11>=Parametres!$B$14,3,IF(W11>=Parametres!$B$15,2,1))) | Y11: =IF(COUNTA(J11:L11)<3,"",AVERAGE(MATCH(J11,Parametres!$B$4:$B$6,0),MATCH(K11,Parametres!$B$4:$B$6,0),MATCH(L11,Parametres!$B$4:$B$6,0))) | Z11: =IF(Y11="","",IF(Y11>=Parametres!$B$14,3,IF(Y11>=Parametres!$B$15,2,1))) | AA11: =IF(R11="","",MATCH(R11,Parametres!$B$18:$B$22,0))
P12: =IF(X12="","",INDEX(Parametres!$B$4:$B$6,X12)) | Q12: =IF(Z12="","",INDEX(Parametres!$B$4:$B$6,Z12)) | R12: =IF(OR(X12="",Z12=""),"",INDEX(Parametres!$B$26:$D$28,X12,Z12)) | S12: =IF(OR(AA12="",I12=""),"",INDEX(Parametres!$B$18:$B$22,MAX(1,MIN(5,AA12+2-MATCH(I12,Parametres!$B$9:$B$11,0))))) | T12: =IF(Z12="","",IF(AND(Z12=3,M12="C"),"Vérifier : activation élevée sans lien géopolitique établi (niveau C)",IF(AND(Z12>=2,M12=""),"Renseigner le niveau de preuve",""))) | W12: =IF(COUNTA(E12:H12)<4,"",AVERAGE(MATCH(E12,Parametres!$B$4:$B$6,0),MATCH(F12,Parametres!$B$4:$B$6,0),MATCH(G12,Parametres!$B$4:$B$6,0),MATCH(H12,Parametres!$B$4:$B$6,0))) | X12: =IF(W12="","",IF(W12>=Parametres!$B$14,3,IF(W12>=Parametres!$B$15,2,1))) | Y12: =IF(COUNTA(J12:L12)<3,"",AVERAGE(MATCH(J12,Parametres!$B$4:$B$6,0),MATCH(K12,Parametres!$B$4:$B$6,0),MATCH(L12,Parametres!$B$4:$B$6,0))) | Z12: =IF(Y12="","",IF(Y12>=Parametres!$B$14,3,IF(Y12>=Parametres!$B$15,2,1))) | AA12: =IF(R12="","",MATCH(R12,Parametres!$B$18:$B$22,0))
P13: =IF(X13="","",INDEX(Parametres!$B$4:$B$6,X13)) | Q13: =IF(Z13="","",INDEX(Parametres!$B$4:$B$6,Z13)) | R13: =IF(OR(X13="",Z13=""),"",INDEX(Parametres!$B$26:$D$28,X13,Z13)) | S13: =IF(OR(AA13="",I13=""),"",INDEX(Parametres!$B$18:$B$22,MAX(1,MIN(5,AA13+2-MATCH(I13,Parametres!$B$9:$B$11,0))))) | T13: =IF(Z13="","",IF(AND(Z13=3,M13="C"),"Vérifier : activation élevée sans lien géopolitique établi (niveau C)",IF(AND(Z13>=2,M13=""),"Renseigner le niveau de preuve",""))) | W13: =IF(COUNTA(E13:H13)<4,"",AVERAGE(MATCH(E13,Parametres!$B$4:$B$6,0),MATCH(F13,Parametres!$B$4:$B$6,0),MATCH(G13,Parametres!$B$4:$B$6,0),MATCH(H13,Parametres!$B$4:$B$6,0))) | X13: =IF(W13="","",IF(W13>=Parametres!$B$14,3,IF(W13>=Parametres!$B$15,2,1))) | Y13: =IF(COUNTA(J13:L13)<3,"",AVERAGE(MATCH(J13,Parametres!$B$4:$B$6,0),MATCH(K13,Parametres!$B$4:$B$6,0),MATCH(L13,Parametres!$B$4:$B$6,0))) | Z13: =IF(Y13="","",IF(Y13>=Parametres!$B$14,3,IF(Y13>=Parametres!$B$15,2,1))) | AA13: =IF(R13="","",MATCH(R13,Parametres!$B$18:$B$22,0))
P14: =IF(X14="","",INDEX(Parametres!$B$4:$B$6,X14)) | Q14: =IF(Z14="","",INDEX(Parametres!$B$4:$B$6,Z14)) | R14: =IF(OR(X14="",Z14=""),"",INDEX(Parametres!$B$26:$D$28,X14,Z14)) | S14: =IF(OR(AA14="",I14=""),"",INDEX(Parametres!$B$18:$B$22,MAX(1,MIN(5,AA14+2-MATCH(I14,Parametres!$B$9:$B$11,0))))) | T14: =IF(Z14="","",IF(AND(Z14=3,M14="C"),"Vérifier : activation élevée sans lien géopolitique établi (niveau C)",IF(AND(Z14>=2,M14=""),"Renseigner le niveau de preuve",""))) | W14: =IF(COUNTA(E14:H14)<4,"",AVERAGE(MATCH(E14,Parametres!$B$4:$B$6,0),MATCH(F14,Parametres!$B$4:$B$6,0),MATCH(G14,Parametres!$B$4:$B$6,0),MATCH(H14,Parametres!$B$4:$B$6,0))) | X14: =IF(W14="","",IF(W14>=Parametres!$B$14,3,IF(W14>=Parametres!$B$15,2,1))) | Y14: =IF(COUNTA(J14:L14)<3,"",AVERAGE(MATCH(J14,Parametres!$B$4:$B$6,0),MATCH(K14,Parametres!$B$4:$B$6,0),MATCH(L14,Parametres!$B$4:$B$6,0))) | Z14: =IF(Y14="","",IF(Y14>=Parametres!$B$14,3,IF(Y14>=Parametres!$B$15,2,1))) | AA14: =IF(R14="","",MATCH(R14,Parametres!$B$18:$B$22,0))
P15: =IF(X15="","",INDEX(Parametres!$B$4:$B$6,X15)) | Q15: =IF(Z15="","",INDEX(Parametres!$B$4:$B$6,Z15)) | R15: =IF(OR(X15="",Z15=""),"",INDEX(Parametres!$B$26:$D$28,X15,Z15)) | S15: =IF(OR(AA15="",I15=""),"",INDEX(Parametres!$B$18:$B$22,MAX(1,MIN(5,AA15+2-MATCH(I15,Parametres!$B$9:$B$11,0))))) | T15: =IF(Z15="","",IF(AND(Z15=3,M15="C"),"Vérifier : activation élevée sans lien géopolitique établi (niveau C)",IF(AND(Z15>=2,M15=""),"Renseigner le niveau de preuve",""))) | W15: =IF(COUNTA(E15:H15)<4,"",AVERAGE(MATCH(E15,Parametres!$B$4:$B$6,0),MATCH(F15,Parametres!$B$4:$B$6,0),MATCH(G15,Parametres!$B$4:$B$6,0),MATCH(H15,Parametres!$B$4:$B$6,0))) | X15: =IF(W15="","",IF(W15>=Parametres!$B$14,3,IF(W15>=Parametres!$B$15,2,1))) | Y15: =IF(COUNTA(J15:L15)<3,"",AVERAGE(MATCH(J15,Parametres!$B$4:$B$6,0),MATCH(K15,Parametres!$B$4:$B$6,0),MATCH(L15,Parametres!$B$4:$B$6,0))) | Z15: =IF(Y15="","",IF(Y15>=Parametres!$B$14,3,IF(Y15>=Parametres!$B$15,2,1))) | AA15: =IF(R15="","",MATCH(R15,Parametres!$B$18:$B$22,0))
P16: =IF(X16="","",INDEX(Parametres!$B$4:$B$6,X16)) | Q16: =IF(Z16="","",INDEX(Parametres!$B$4:$B$6,Z16)) | R16: =IF(OR(X16="",Z16=""),"",INDEX(Parametres!$B$26:$D$28,X16,Z16)) | S16: =IF(OR(AA16="",I16=""),"",INDEX(Parametres!$B$18:$B$22,MAX(1,MIN(5,AA16+2-MATCH(I16,Parametres!$B$9:$B$11,0))))) | T16: =IF(Z16="","",IF(AND(Z16=3,M16="C"),"Vérifier : activation élevée sans lien géopolitique établi (niveau C)",IF(AND(Z16>=2,M16=""),"Renseigner le niveau de preuve",""))) | W16: =IF(COUNTA(E16:H16)<4,"",AVERAGE(MATCH(E16,Parametres!$B$4:$B$6,0),MATCH(F16,Parametres!$B$4:$B$6,0),MATCH(G16,Parametres!$B$4:$B$6,0),MATCH(H16,Parametres!$B$4:$B$6,0))) | X16: =IF(W16="","",IF(W16>=Parametres!$B$14,3,IF(W16>=Parametres!$B$15,2,1))) | Y16: =IF(COUNTA(J16:L16)<3,"",AVERAGE(MATCH(J16,Parametres!$B$4:$B$6,0),MATCH(K16,Parametres!$B$4:$B$6,0),MATCH(L16,Parametres!$B$4:$B$6,0))) | Z16: =IF(Y16="","",IF(Y16>=Parametres!$B$14,3,IF(Y16>=Parametres!$B$15,2,1))) | AA16: =IF(R16="","",MATCH(R16,Parametres!$B$18:$B$22,0))
P17: =IF(X17="","",INDEX(Parametres!$B$4:$B$6,X17)) | Q17: =IF(Z17="","",INDEX(Parametres!$B$4:$B$6,Z17)) | R17: =IF(OR(X17="",Z17=""),"",INDEX(Parametres!$B$26:$D$28,X17,Z17)) | S17: =IF(OR(AA17="",I17=""),"",INDEX(Parametres!$B$18:$B$22,MAX(1,MIN(5,AA17+2-MATCH(I17,Parametres!$B$9:$B$11,0))))) | T17: =IF(Z17="","",IF(AND(Z17=3,M17="C"),"Vérifier : activation élevée sans lien géopolitique établi (niveau C)",IF(AND(Z17>=2,M17=""),"Renseigner le niveau de preuve",""))) | W17: =IF(COUNTA(E17:H17)<4,"",AVERAGE(MATCH(E17,Parametres!$B$4:$B$6,0),MATCH(F17,Parametres!$B$4:$B$6,0),MATCH(G17,Parametres!$B$4:$B$6,0),MATCH(H17,Parametres!$B$4:$B$6,0))) | X17: =IF(W17="","",IF(W17>=Parametres!$B$14,3,IF(W17>=Parametres!$B$15,2,1))) | Y17: =IF(COUNTA(J17:L17)<3,"",AVERAGE(MATCH(J17,Parametres!$B$4:$B$6,0),MATCH(K17,Parametres!$B$4:$B$6,0),MATCH(L17,Parametres!$B$4:$B$6,0))) | Z17: =IF(Y17="","",IF(Y17>=Parametres!$B$14,3,IF(Y17>=Parametres!$B$15,2,1))) | AA17: =IF(R17="","",MATCH(R17,Parametres!$B$18:$B$22,0))
P18: =IF(X18="","",INDEX(Parametres!$B$4:$B$6,X18)) | Q18: =IF(Z18="","",INDEX(Parametres!$B$4:$B$6,Z18)) | R18: =IF(OR(X18="",Z18=""),"",INDEX(Parametres!$B$26:$D$28,X18,Z18)) | S18: =IF(OR(AA18="",I18=""),"",INDEX(Parametres!$B$18:$B$22,MAX(1,MIN(5,AA18+2-MATCH(I18,Parametres!$B$9:$B$11,0))))) | T18: =IF(Z18="","",IF(AND(Z18=3,M18="C"),"Vérifier : activation élevée sans lien géopolitique établi (niveau C)",IF(AND(Z18>=2,M18=""),"Renseigner le niveau de preuve",""))) | W18: =IF(COUNTA(E18:H18)<4,"",AVERAGE(MATCH(E18,Parametres!$B$4:$B$6,0),MATCH(F18,Parametres!$B$4:$B$6,0),MATCH(G18,Parametres!$B$4:$B$6,0),MATCH(H18,Parametres!$B$4:$B$6,0))) | X18: =IF(W18="","",IF(W18>=Parametres!$B$14,3,IF(W18>=Parametres!$B$15,2,1))) | Y18: =IF(COUNTA(J18:L18)<3,"",AVERAGE(MATCH(J18,Parametres!$B$4:$B$6,0),MATCH(K18,Parametres!$B$4:$B$6,0),MATCH(L18,Parametres!$B$4:$B$6,0))) | Z18: =IF(Y18="","",IF(Y18>=Parametres!$B$14,3,IF(Y18>=Parametres!$B$15,2,1))) | AA18: =IF(R18="","",MATCH(R18,Parametres!$B$18:$B$22,0))
... P45: =IF(X45="","",INDEX(Parametres!$B$4:$B$6,X45)) | Q45: =IF(Z45="","",INDEX(Parametres!$B$4:$B$6,Z45)) | R45: =IF(OR(X45="",Z45=""),"",INDEX(Parametres!$B$26:$D$28,X45,Z45)) | S45: =IF(OR(AA45="",I45=""),"",INDEX(Parametres!$B$18:$B$22,MAX(1,MIN(5,AA45+2-MATCH(I45,Parametres!$B$9:$B$11,0))))) | T45: =IF(Z45="","",IF(AND(Z45=3,M45="C"),"Vérifier : activation élevée sans lien géopolitique établi (niveau C)",IF(AND(Z45>=2,M45=""),"Renseigner le niveau de preuve",""))) | W45: =IF(COUNTA(E45:H45)<4,"",AVERAGE(MATCH(E45,Parametres!$B$4:$B$6,0),MATCH(F45,Parametres!$B$4:$B$6,0),MATCH(G45,Parametres!$B$4:$B$6,0),MATCH(H45,Parametres!$B$4:$B$6,0))) | X45: =IF(W45="","",IF(W45>=Parametres!$B$14,3,IF(W45>=Parametres!$B$15,2,1))) | Y45: =IF(COUNTA(J45:L45)<3,"",AVERAGE(MATCH(J45,Parametres!$B$4:$B$6,0),MATCH(K45,Parametres!$B$4:$B$6,0),MATCH(L45,Parametres!$B$4:$B$6,0))) | Z45: =IF(Y45="","",IF(Y45>=Parametres!$B$14,3,IF(Y45>=Parametres!$B$15,2,1))) | AA45: =IF(R45="","",MATCH(R45,Parametres!$B$18:$B$22,0))

Sheet Synthese
A1: Synthèse des dépendances analysées
A3: Répartition par priorité finale
A4: Priorité | B4: Nombre
A5: Traiter en priorité | B5: =COUNTIF(Fiche!$S$6:$S$45,A5) -> 0
A6: Traiter | B6: =COUNTIF(Fiche!$S$6:$S$45,A6) -> 1
A7: Surveiller | B7: =COUNTIF(Fiche!$S$6:$S$45,A7) -> 0
A8: Accepter et suivre | B8: =COUNTIF(Fiche!$S$6:$S$45,A8) -> 0
A9: Accepter | B9: =COUNTIF(Fiche!$S$6:$S$45,A9) -> 0
A10: Total | B10: =SUM(B5:B9) -> 1
A12: Répartition par catégorie et par priorité
A13: Catégorie | B13: Traiter en priorité | C13: Traiter | D13: Surveiller | E13: Accepter et suivre | F13: Accepter | G13: Total
A14: Logicielle | B14: =COUNTIFS(Fiche!$C$6:$C$45,$A14,Fiche!$S$6:$S$45,B$13) -> 0 | C14: =COUNTIFS(Fiche!$C$6:$C$45,$A14,Fiche!$S$6:$S$45,C$13) -> 0 | D14: =COUNTIFS(Fiche!$C$6:$C$45,$A14,Fiche!$S$6:$S$45,D$13) -> 0 | E14: =COUNTIFS(Fiche!$C$6:$C$45,$A14,Fiche!$S$6:$S$45,E$13) -> 0 | F14: =COUNTIFS(Fiche!$C$6:$C$45,$A14,Fiche!$S$6:$S$45,F$13) -> 0 | G14: =SUM(B14:F14) -> 0
A15: Industrielle (OT) | B15: =COUNTIFS(Fiche!$C$6:$C$45,$A15,Fiche!$S$6:$S$45,B$13) -> 0 | C15: =COUNTIFS(Fiche!$C$6:$C$45,$A15,Fiche!$S$6:$S$45,C$13) -> 1 | D15: =COUNTIFS(Fiche!$C$6:$C$45,$A15,Fiche!$S$6:$S$45,D$13) -> 0 | E15: =COUNTIFS(Fiche!$C$6:$C$45,$A15,Fiche!$S$6:$S$45,E$13) -> 0 | F15: =COUNTIFS(Fiche!$C$6:$C$45,$A15,Fiche!$S$6:$S$45,F$13) -> 0 | G15: =SUM(B15:F15) -> 1
A16: Intermédiaire de service | B16: =COUNTIFS(Fiche!$C$6:$C$45,$A16,Fiche!$S$6:$S$45,B$13) -> 0 | C16: =COUNTIFS(Fiche!$C$6:$C$45,$A16,Fiche!$S$6:$S$45,C$13) -> 0 | D16: =COUNTIFS(Fiche!$C$6:$C$45,$A16,Fiche!$S$6:$S$45,D$13) -> 0 | E16: =COUNTIFS(Fiche!$C$6:$C$45,$A16,Fiche!$S$6:$S$45,E$13) -> 0 | F16: =COUNTIFS(Fiche!$C$6:$C$45,$A16,Fiche!$S$6:$S$45,F$13) -> 0 | G16: =SUM(B16:F16) -> 0
A17: Matérielle | B17: =COUNTIFS(Fiche!$C$6:$C$45,$A17,Fiche!$S$6:$S$45,B$13) -> 0 | C17: =COUNTIFS(Fiche!$C$6:$C$45,$A17,Fiche!$S$6:$S$45,C$13) -> 0 | D17: =COUNTIFS(Fiche!$C$6:$C$45,$A17,Fiche!$S$6:$S$45,D$13) -> 0 | E17: =COUNTIFS(Fiche!$C$6:$C$45,$A17,Fiche!$S$6:$S$45,E$13) -> 0 | F17: =COUNTIFS(Fiche!$C$6:$C$45,$A17,Fiche!$S$6:$S$45,F$13) -> 0 | G17: =SUM(B17:F17) -> 0
A18: Algorithmique | B18: =COUNTIFS(Fiche!$C$6:$C$45,$A18,Fiche!$S$6:$S$45,B$13) -> 0 | C18: =COUNTIFS(Fiche!$C$6:$C$45,$A18,Fiche!$S$6:$S$45,C$13) -> 0 | D18: =COUNTIFS(Fiche!$C$6:$C$45,$A18,Fiche!$S$6:$S$45,D$13) -> 0 | E18: =COUNTIFS(Fiche!$C$6:$C$45,$A18,Fiche!$S$6:$S$45,E$13) -> 0 | F18: =COUNTIFS(Fiche!$C$6:$C$45,$A18,Fiche!$S$6:$S$45,F$13) -> 0 | G18: =SUM(B18:F18) -> 0
A20: Exposition structurelle × activation géopolitique (nombre de dépendances)
A21: Exposition \ Activation | B21: Faible | C21: Modérée | D21: Élevée
A22: Élevée | B22: =COUNTIFS(Fiche!$X$6:$X$45,3,Fiche!$Z$6:$Z$45,1) -> 1 | C22: =COUNTIFS(Fiche!$X$6:$X$45,3,Fiche!$Z$6:$Z$45,2) -> 0 | D22: =COUNTIFS(Fiche!$X$6:$X$45,3,Fiche!$Z$6:$Z$45,3) -> 0
A23: Modérée | B23: =COUNTIFS(Fiche!$X$6:$X$45,2,Fiche!$Z$6:$Z$45,1) -> 0 | C23: =COUNTIFS(Fiche!$X$6:$X$45,2,Fiche!$Z$6:$Z$45,2) -> 0 | D23: =COUNTIFS(Fiche!$X$6:$X$45,2,Fiche!$Z$6:$Z$45,3) -> 0
A24: Faible | B24: =COUNTIFS(Fiche!$X$6:$X$45,1,Fiche!$Z$6:$Z$45,1) -> 0 | C24: =COUNTIFS(Fiche!$X$6:$X$45,1,Fiche!$Z$6:$Z$45,2) -> 0 | D24: =COUNTIFS(Fiche!$X$6:$X$45,1,Fiche!$Z$6:$Z$45,3) -> 0

Sheet Parametres
A1: Paramètres (modifiables)
A3: Niveaux d'exposition et d'activation (ordre croissant)
A4: 1 | B4: Faible
A5: 2 | B5: Modérée
A6: 3 | B6: Élevée
A8: Niveaux de résilience (ordre croissant)
A9: 1 | B9: Faible
A10: 2 | B10: Partielle
A11: 3 | B11: Solide
A13: Seuils de la moyenne
A14: Seuil « élevée » (moyenne ≥) | B14: 2.5
A15: Seuil « modérée » (moyenne ≥) | B15: 1.75
A17: Échelle de priorité (ordre croissant)
A18: 1 | B18: Accepter
A19: 2 | B19: Accepter et suivre
A20: 3 | B20: Surveiller
A21: 4 | B21: Traiter
A22: 5 | B22: Traiter en priorité
A24: Matrice de priorité de base (lignes : exposition ; colonnes : activation)
B25: Faible | C25: Modérée | D25: Élevée
A26: Faible | B26: Accepter | C26: Accepter et suivre | D26: Surveiller
A27: Modérée | B27: Accepter et suivre | C27: Surveiller | D27: Traiter
A28: Élevée | B28: Surveiller | C28: Traiter | D28: Traiter en priorité
A30: Niveaux de preuve
A31: A | B31: Attribution ou décision officielle documentée (autorité publique, inculpation, mesure formelle)
A32: B | B32: Contexte géopolitique documenté, sans attribution formelle
A33: C | B33: Aucun lien géopolitique établi (impact systémique seul)
A34: D | B34: Perturbation résultant d'une décision ou d'une politique publique non cyber (restriction, sanction, contrôle à l'export)
A35: En cas de doute entre deux niveaux, retenir celui qui suppose le moins de lien géopolitique (annexe A de l'article).
A37: Catégories de dépendances
B38: Logicielle
B39: Industrielle (OT)
B40: Intermédiaire de service
B41: Matérielle
B42: Algorithmique
A44: Décisions possibles
B45: Réduire
B46: Diversifier
B47: Surveiller
B48: Compenser
...
